Workbook

Sheet Start_Here
A1: IT Service Desk Tickets, October 2025 to September 2026
A2: Marrowstone Advisory Group (fictional). Lab workbook for Module 6: Copilot in Excel.
A3: Synthetic training data. All names, organizations, and data are fictional.
A6: Your lab in four steps (25 minutes)
A7: Step | B7: What to do | C7: Check your work
A8: 01 Format table | B8: Go to the Tickets sheet. Click any cell in the data and press Ctrl+T. Confirm that My table has headers is selected. On the Table Design tab, name the table Tickets. Check that there is one header row and every header is unique. | C8: Filter buttons appear on every header. The table has 13,147 rows and 25 columns.
A9: 02 Query insights | B9: Open Copilot and ask for three operational insights about ticket volume and resolution. Write the prompt with Goal, Context, Source, and Expectations. If Copilot cannot analyze the full table, name the Summary sheet as your Source (blocks C, E, and F are a good place to start). | C9: Pick one number Copilot gives you and find it on the Summary sheet or with a filter. Type it on the Check_Your_Work sheet.
A10: 03 Add formulas | B10: Ask Copilot to write a formula for a new column named Response_Minutes: the minutes from Opened_At to First_Response_At, blank when there is no first response. Type the header in Z1 and paste the formula in Z2. Then copy the formula from X2 (SLA_Target_Hours), paste it into Copilot, and ask for a plain English explanation and a modern alternative. | C10: The spot-check bench on Check_Your_Work turns green when your column is right.
A11: 04 Build visual | B11: Ask Copilot which PivotTable layout shows ticket counts by Category and Priority, and which chart suits it. Build the PivotTable from the Tickets table, then add a bar chart. If your Copilot offers to insert them for you, let it, then check them. | C11: Confirm the chart's data range. A Grand Total row or column must not be plotted as a bar.
A13: Sheets in this workbook
A14: Sheet | B14: What it holds | C14: How it is used
A15: Summary | B15: Six small summary tables. Every number is a live formula over the Tickets sheet. | C15: A reliable source for insight prompts and for cross-checking numbers
A16: Tickets | B16: 13,147 tickets, one row per ticket, 25 columns. Left as a plain range on purpose. | C16: Convert to a table with Ctrl+T, then add formula columns and build PivotTables
A17: SLA_Policy | B17: Response and resolution targets by priority, and the report date. | C17: Looked up by the two formula columns on Tickets
A18: Sites | B18: Nine sites with headcount and whether support staff are on site. | C18: Lookup
A19: Departments | B19: Twelve departments with headcount. | C19: Lookup
A20: Assignment_Groups | B20: Eight support groups with tier, lead, and scope. | C20: Lookup
A21: Categories | B21: 36 subcategories mapped to eight categories. | C21: Lookup
A22: Change_Calendar | B22: Change records with a live count of linked tickets. | C22: First place to look when ticket volume spikes
A23: Check_Your_Work | B23: A spot-check bench for your new column and a short scoreboard. | C23: Verify what Copilot gives you before you rely on it
A25: How SLA works in this dataset
A26: Resolution targets by priority: P1 4 hours, P2 8 hours, P3 72 hours, P4 120 hours. The clock runs on calendar hours.
A27: Met means the ticket was resolved within its target. Breached means it was resolved late.
A28: Open tickets are measured against the report date, September 30, 2026 at 11:59 PM, which is stored on the SLA_Policy sheet.
A29: Cancelled tickets are excluded. Breach rate on the Summary sheet is Breached divided by Met plus Breached.
A31: Columns on the Tickets sheet
A32: Column | B32: Header | C32: Meaning | D32: Example or values
A33: A | B33: Ticket_ID | C33: Unique ticket number, assigned in the order tickets were opened | D33: SD-48211
A34: B | B34: Opened_At | C34: Date and time the ticket was opened (Eastern Time) | D34: 2026-09-09 08:51
A35: C | B35: First_Response_At | C35: Date and time of the first response from support. Blank if there has been no response | D35: 2026-09-09 08:55
A36: D | B36: Resolved_At | C36: Date and time the ticket was resolved. Blank if the ticket is open or cancelled | D36: 2026-09-09 12:57
A37: E | B37: Status | C37: Where the ticket stands on the report date | D37: New, In Progress, On Hold, Resolved, Closed, Cancelled
A38: F | B38: Priority | C38: Urgency and impact. Sets the SLA targets | D38: P1 - Critical, P2 - High, P3 - Medium, P4 - Low
A39: G | B39: Ticket_Type | C39: Something is broken (Incident) or something is needed (Service Request) | D39: Incident, Service Request
A40: H | B40: Category | C40: One of eight categories. See the Categories sheet | D40: Network and VPN
A41: I | B41: Subcategory | C41: One of 36 subcategories. See the Categories sheet | D41: VPN connectivity
A42: J | B42: Short_Description | C42: The requester's summary of the issue | D42: VPN disconnects every few minutes
A43: K | B43: Site_Code | C43: The requester's site. See the Sites sheet | D43: HQ, ANX, NGT, LKS, SMR, CBO, HPF, GRV, RMT
... A57: Y | B57: SLA_Result | C57: Formula. Compares the time to resolve with the target | D57: Met, Breached, Open - On Track, Open - Breached, Excluded

Sheet Summary
A1: Service desk summary, October 2025 to September 2026
A2: Every number on this sheet is a live formula over the Tickets sheet. SLA results use the report date on the SLA_Policy sheet.
A4: A. Tickets opened, by month and category
A5: Month | B5: Account and Access | C5: Email and Collaboration | D5: Hardware | E5: Mobile and Field Devices | F5: Network and VPN | G5: Printing and Scanning | H5: Security | I5: Software | J5: Total
A6: 45931 | B6: =COUNTIFS(Tickets!$B:$B,">="&$A6,Tickets!$B:$B,"<"&EDATE($A6,1),Tickets!$H:$H,B$5) -> 393 | C6: =COUNTIFS(Tickets!$B:$B,">="&$A6,Tickets!$B:$B,"<"&EDATE($A6,1),Tickets!$H:$H,C$5) -> 184 | D6: =COUNTIFS(Tickets!$B:$B,">="&$A6,Tickets!$B:$B,"<"&EDATE($A6,1),Tickets!$H:$H,D$5) -> 149 | E6: =COUNTIFS(Tickets!$B:$B,">="&$A6,Tickets!$B:$B,"<"&EDATE($A6,1),Tickets!$H:$H,E$5) -> 100 | F6: =COUNTIFS(Tickets!$B:$B,">="&$A6,Tickets!$B:$B,"<"&EDATE($A6,1),Tickets!$H:$H,F$5) -> 124 | G6: =COUNTIFS(Tickets!$B:$B,">="&$A6,Tickets!$B:$B,"<"&EDATE($A6,1),Tickets!$H:$H,G$5) -> 53 | H6: =COUNTIFS(Tickets!$B:$B,">="&$A6,Tickets!$B:$B,"<"&EDATE($A6,1),Tickets!$H:$H,H$5) -> 75 | I6: =COUNTIFS(Tickets!$B:$B,">="&$A6,Tickets!$B:$B,"<"&EDATE($A6,1),Tickets!$H:$H,I$5) -> 181 | J6: =SUM(B6:I6) -> 1259
A7: 45962 | B7: =COUNTIFS(Tickets!$B:$B,">="&$A7,Tickets!$B:$B,"<"&EDATE($A7,1),Tickets!$H:$H,B$5) -> 190 | C7: =COUNTIFS(Tickets!$B:$B,">="&$A7,Tickets!$B:$B,"<"&EDATE($A7,1),Tickets!$H:$H,C$5) -> 141 | D7: =COUNTIFS(Tickets!$B:$B,">="&$A7,Tickets!$B:$B,"<"&EDATE($A7,1),Tickets!$H:$H,D$5) -> 111 | E7: =COUNTIFS(Tickets!$B:$B,">="&$A7,Tickets!$B:$B,"<"&EDATE($A7,1),Tickets!$H:$H,E$5) -> 92 | F7: =COUNTIFS(Tickets!$B:$B,">="&$A7,Tickets!$B:$B,"<"&EDATE($A7,1),Tickets!$H:$H,F$5) -> 107 | G7: =COUNTIFS(Tickets!$B:$B,">="&$A7,Tickets!$B:$B,"<"&EDATE($A7,1),Tickets!$H:$H,G$5) -> 75 | H7: =COUNTIFS(Tickets!$B:$B,">="&$A7,Tickets!$B:$B,"<"&EDATE($A7,1),Tickets!$H:$H,H$5) -> 51 | I7: =COUNTIFS(Tickets!$B:$B,">="&$A7,Tickets!$B:$B,"<"&EDATE($A7,1),Tickets!$H:$H,I$5) -> 133 | J7: =SUM(B7:I7) -> 900
A8: 45992 | B8: =COUNTIFS(Tickets!$B:$B,">="&$A8,Tickets!$B:$B,"<"&EDATE($A8,1),Tickets!$H:$H,B$5) -> 178 | C8: =COUNTIFS(Tickets!$B:$B,">="&$A8,Tickets!$B:$B,"<"&EDATE($A8,1),Tickets!$H:$H,C$5) -> 156 | D8: =COUNTIFS(Tickets!$B:$B,">="&$A8,Tickets!$B:$B,"<"&EDATE($A8,1),Tickets!$H:$H,D$5) -> 104 | E8: =COUNTIFS(Tickets!$B:$B,">="&$A8,Tickets!$B:$B,"<"&EDATE($A8,1),Tickets!$H:$H,E$5) -> 79 | F8: =COUNTIFS(Tickets!$B:$B,">="&$A8,Tickets!$B:$B,"<"&EDATE($A8,1),Tickets!$H:$H,F$5) -> 94 | G8: =COUNTIFS(Tickets!$B:$B,">="&$A8,Tickets!$B:$B,"<"&EDATE($A8,1),Tickets!$H:$H,G$5) -> 47 | H8: =COUNTIFS(Tickets!$B:$B,">="&$A8,Tickets!$B:$B,"<"&EDATE($A8,1),Tickets!$H:$H,H$5) -> 47 | I8: =COUNTIFS(Tickets!$B:$B,">="&$A8,Tickets!$B:$B,"<"&EDATE($A8,1),Tickets!$H:$H,I$5) -> 136 | J8: =SUM(B8:I8) -> 841
A9: 46023 | B9: =COUNTIFS(Tickets!$B:$B,">="&$A9,Tickets!$B:$B,"<"&EDATE($A9,1),Tickets!$H:$H,B$5) -> 398 | C9: =COUNTIFS(Tickets!$B:$B,">="&$A9,Tickets!$B:$B,"<"&EDATE($A9,1),Tickets!$H:$H,C$5) -> 156 | D9: =COUNTIFS(Tickets!$B:$B,">="&$A9,Tickets!$B:$B,"<"&EDATE($A9,1),Tickets!$H:$H,D$5) -> 124 | E9: =COUNTIFS(Tickets!$B:$B,">="&$A9,Tickets!$B:$B,"<"&EDATE($A9,1),Tickets!$H:$H,E$5) -> 92 | F9: =COUNTIFS(Tickets!$B:$B,">="&$A9,Tickets!$B:$B,"<"&EDATE($A9,1),Tickets!$H:$H,F$5) -> 89 | G9: =COUNTIFS(Tickets!$B:$B,">="&$A9,Tickets!$B:$B,"<"&EDATE($A9,1),Tickets!$H:$H,G$5) -> 89 | H9: =COUNTIFS(Tickets!$B:$B,">="&$A9,Tickets!$B:$B,"<"&EDATE($A9,1),Tickets!$H:$H,H$5) -> 97 | I9: =COUNTIFS(Tickets!$B:$B,">="&$A9,Tickets!$B:$B,"<"&EDATE($A9,1),Tickets!$H:$H,I$5) -> 141 | J9: =SUM(B9:I9) -> 1186
A10: 46054 | B10: =COUNTIFS(Tickets!$B:$B,">="&$A10,Tickets!$B:$B,"<"&EDATE($A10,1),Tickets!$H:$H,B$5) -> 238 | C10: =COUNTIFS(Tickets!$B:$B,">="&$A10,Tickets!$B:$B,"<"&EDATE($A10,1),Tickets!$H:$H,C$5) -> 156 | D10: =COUNTIFS(Tickets!$B:$B,">="&$A10,Tickets!$B:$B,"<"&EDATE($A10,1),Tickets!$H:$H,D$5) -> 134 | E10: =COUNTIFS(Tickets!$B:$B,">="&$A10,Tickets!$B:$B,"<"&EDATE($A10,1),Tickets!$H:$H,E$5) -> 112 | F10: =COUNTIFS(Tickets!$B:$B,">="&$A10,Tickets!$B:$B,"<"&EDATE($A10,1),Tickets!$H:$H,F$5) -> 109 | G10: =COUNTIFS(Tickets!$B:$B,">="&$A10,Tickets!$B:$B,"<"&EDATE($A10,1),Tickets!$H:$H,G$5) -> 67 | H10: =COUNTIFS(Tickets!$B:$B,">="&$A10,Tickets!$B:$B,"<"&EDATE($A10,1),Tickets!$H:$H,H$5) -> 67 | I10: =COUNTIFS(Tickets!$B:$B,">="&$A10,Tickets!$B:$B,"<"&EDATE($A10,1),Tickets!$H:$H,I$5) -> 158 | J10: =SUM(B10:I10) -> 1041
A11: 46082 | B11: =COUNTIFS(Tickets!$B:$B,">="&$A11,Tickets!$B:$B,"<"&EDATE($A11,1),Tickets!$H:$H,B$5) -> 265 | C11: =COUNTIFS(Tickets!$B:$B,">="&$A11,Tickets!$B:$B,"<"&EDATE($A11,1),Tickets!$H:$H,C$5) -> 176 | D11: =COUNTIFS(Tickets!$B:$B,">="&$A11,Tickets!$B:$B,"<"&EDATE($A11,1),Tickets!$H:$H,D$5) -> 143 | E11: =COUNTIFS(Tickets!$B:$B,">="&$A11,Tickets!$B:$B,"<"&EDATE($A11,1),Tickets!$H:$H,E$5) -> 118 | F11: =COUNTIFS(Tickets!$B:$B,">="&$A11,Tickets!$B:$B,"<"&EDATE($A11,1),Tickets!$H:$H,F$5) -> 649 | G11: =COUNTIFS(Tickets!$B:$B,">="&$A11,Tickets!$B:$B,"<"&EDATE($A11,1),Tickets!$H:$H,G$5) -> 56 | H11: =COUNTIFS(Tickets!$B:$B,">="&$A11,Tickets!$B:$B,"<"&EDATE($A11,1),Tickets!$H:$H,H$5) -> 50 | I11: =COUNTIFS(Tickets!$B:$B,">="&$A11,Tickets!$B:$B,"<"&EDATE($A11,1),Tickets!$H:$H,I$5) -> 155 | J11: =SUM(B11:I11) -> 1612
A12: 46113 | B12: =COUNTIFS(Tickets!$B:$B,">="&$A12,Tickets!$B:$B,"<"&EDATE($A12,1),Tickets!$H:$H,B$5) -> 244 | C12: =COUNTIFS(Tickets!$B:$B,">="&$A12,Tickets!$B:$B,"<"&EDATE($A12,1),Tickets!$H:$H,C$5) -> 181 | D12: =COUNTIFS(Tickets!$B:$B,">="&$A12,Tickets!$B:$B,"<"&EDATE($A12,1),Tickets!$H:$H,D$5) -> 139 | E12: =COUNTIFS(Tickets!$B:$B,">="&$A12,Tickets!$B:$B,"<"&EDATE($A12,1),Tickets!$H:$H,E$5) -> 90 | F12: =COUNTIFS(Tickets!$B:$B,">="&$A12,Tickets!$B:$B,"<"&EDATE($A12,1),Tickets!$H:$H,F$5) -> 111 | G12: =COUNTIFS(Tickets!$B:$B,">="&$A12,Tickets!$B:$B,"<"&EDATE($A12,1),Tickets!$H:$H,G$5) -> 59 | H12: =COUNTIFS(Tickets!$B:$B,">="&$A12,Tickets!$B:$B,"<"&EDATE($A12,1),Tickets!$H:$H,H$5) -> 61 | I12: =COUNTIFS(Tickets!$B:$B,">="&$A12,Tickets!$B:$B,"<"&EDATE($A12,1),Tickets!$H:$H,I$5) -> 164 | J12: =SUM(B12:I12) -> 1049
A13: 46143 | B13: =COUNTIFS(Tickets!$B:$B,">="&$A13,Tickets!$B:$B,"<"&EDATE($A13,1),Tickets!$H:$H,B$5) -> 221 | C13: =COUNTIFS(Tickets!$B:$B,">="&$A13,Tickets!$B:$B,"<"&EDATE($A13,1),Tickets!$H:$H,C$5) -> 125 | D13: =COUNTIFS(Tickets!$B:$B,">="&$A13,Tickets!$B:$B,"<"&EDATE($A13,1),Tickets!$H:$H,D$5) -> 120 | E13: =COUNTIFS(Tickets!$B:$B,">="&$A13,Tickets!$B:$B,"<"&EDATE($A13,1),Tickets!$H:$H,E$5) -> 98 | F13: =COUNTIFS(Tickets!$B:$B,">="&$A13,Tickets!$B:$B,"<"&EDATE($A13,1),Tickets!$H:$H,F$5) -> 123 | G13: =COUNTIFS(Tickets!$B:$B,">="&$A13,Tickets!$B:$B,"<"&EDATE($A13,1),Tickets!$H:$H,G$5) -> 48 | H13: =COUNTIFS(Tickets!$B:$B,">="&$A13,Tickets!$B:$B,"<"&EDATE($A13,1),Tickets!$H:$H,H$5) -> 33 | I13: =COUNTIFS(Tickets!$B:$B,">="&$A13,Tickets!$B:$B,"<"&EDATE($A13,1),Tickets!$H:$H,I$5) -> 129 | J13: =SUM(B13:I13) -> 897
A14: 46174 | B14: =COUNTIFS(Tickets!$B:$B,">="&$A14,Tickets!$B:$B,"<"&EDATE($A14,1),Tickets!$H:$H,B$5) -> 270 | C14: =COUNTIFS(Tickets!$B:$B,">="&$A14,Tickets!$B:$B,"<"&EDATE($A14,1),Tickets!$H:$H,C$5) -> 168 | D14: =COUNTIFS(Tickets!$B:$B,">="&$A14,Tickets!$B:$B,"<"&EDATE($A14,1),Tickets!$H:$H,D$5) -> 148 | E14: =COUNTIFS(Tickets!$B:$B,">="&$A14,Tickets!$B:$B,"<"&EDATE($A14,1),Tickets!$H:$H,E$5) -> 90 | F14: =COUNTIFS(Tickets!$B:$B,">="&$A14,Tickets!$B:$B,"<"&EDATE($A14,1),Tickets!$H:$H,F$5) -> 128 | G14: =COUNTIFS(Tickets!$B:$B,">="&$A14,Tickets!$B:$B,"<"&EDATE($A14,1),Tickets!$H:$H,G$5) -> 65 | H14: =COUNTIFS(Tickets!$B:$B,">="&$A14,Tickets!$B:$B,"<"&EDATE($A14,1),Tickets!$H:$H,H$5) -> 49 | I14: =COUNTIFS(Tickets!$B:$B,">="&$A14,Tickets!$B:$B,"<"&EDATE($A14,1),Tickets!$H:$H,I$5) -> 226 | J14: =SUM(B14:I14) -> 1144
A15: 46204 | B15: =COUNTIFS(Tickets!$B:$B,">="&$A15,Tickets!$B:$B,"<"&EDATE($A15,1),Tickets!$H:$H,B$5) -> 274 | C15: =COUNTIFS(Tickets!$B:$B,">="&$A15,Tickets!$B:$B,"<"&EDATE($A15,1),Tickets!$H:$H,C$5) -> 140 | D15: =COUNTIFS(Tickets!$B:$B,">="&$A15,Tickets!$B:$B,"<"&EDATE($A15,1),Tickets!$H:$H,D$5) -> 141 | E15: =COUNTIFS(Tickets!$B:$B,">="&$A15,Tickets!$B:$B,"<"&EDATE($A15,1),Tickets!$H:$H,E$5) -> 101 | F15: =COUNTIFS(Tickets!$B:$B,">="&$A15,Tickets!$B:$B,"<"&EDATE($A15,1),Tickets!$H:$H,F$5) -> 96 | G15: =COUNTIFS(Tickets!$B:$B,">="&$A15,Tickets!$B:$B,"<"&EDATE($A15,1),Tickets!$H:$H,G$5) -> 55 | H15: =COUNTIFS(Tickets!$B:$B,">="&$A15,Tickets!$B:$B,"<"&EDATE($A15,1),Tickets!$H:$H,H$5) -> 66 | I15: =COUNTIFS(Tickets!$B:$B,">="&$A15,Tickets!$B:$B,"<"&EDATE($A15,1),Tickets!$H:$H,I$5) -> 143 | J15: =SUM(B15:I15) -> 1016
A16: 46235 | B16: =COUNTIFS(Tickets!$B:$B,">="&$A16,Tickets!$B:$B,"<"&EDATE($A16,1),Tickets!$H:$H,B$5) -> 228 | C16: =COUNTIFS(Tickets!$B:$B,">="&$A16,Tickets!$B:$B,"<"&EDATE($A16,1),Tickets!$H:$H,C$5) -> 205 | D16: =COUNTIFS(Tickets!$B:$B,">="&$A16,Tickets!$B:$B,"<"&EDATE($A16,1),Tickets!$H:$H,D$5) -> 147 | E16: =COUNTIFS(Tickets!$B:$B,">="&$A16,Tickets!$B:$B,"<"&EDATE($A16,1),Tickets!$H:$H,E$5) -> 86 | F16: =COUNTIFS(Tickets!$B:$B,">="&$A16,Tickets!$B:$B,"<"&EDATE($A16,1),Tickets!$H:$H,F$5) -> 127 | G16: =COUNTIFS(Tickets!$B:$B,">="&$A16,Tickets!$B:$B,"<"&EDATE($A16,1),Tickets!$H:$H,G$5) -> 64 | H16: =COUNTIFS(Tickets!$B:$B,">="&$A16,Tickets!$B:$B,"<"&EDATE($A16,1),Tickets!$H:$H,H$5) -> 72 | I16: =COUNTIFS(Tickets!$B:$B,">="&$A16,Tickets!$B:$B,"<"&EDATE($A16,1),Tickets!$H:$H,I$5) -> 176 | J16: =SUM(B16:I16) -> 1105
A17: 46266 | B17: =COUNTIFS(Tickets!$B:$B,">="&$A17,Tickets!$B:$B,"<"&EDATE($A17,1),Tickets!$H:$H,B$5) -> 262 | C17: =COUNTIFS(Tickets!$B:$B,">="&$A17,Tickets!$B:$B,"<"&EDATE($A17,1),Tickets!$H:$H,C$5) -> 189 | D17: =COUNTIFS(Tickets!$B:$B,">="&$A17,Tickets!$B:$B,"<"&EDATE($A17,1),Tickets!$H:$H,D$5) -> 132 | E17: =COUNTIFS(Tickets!$B:$B,">="&$A17,Tickets!$B:$B,"<"&EDATE($A17,1),Tickets!$H:$H,E$5) -> 111 | F17: =COUNTIFS(Tickets!$B:$B,">="&$A17,Tickets!$B:$B,"<"&EDATE($A17,1),Tickets!$H:$H,F$5) -> 123 | G17: =COUNTIFS(Tickets!$B:$B,">="&$A17,Tickets!$B:$B,"<"&EDATE($A17,1),Tickets!$H:$H,G$5) -> 55 | H17: =COUNTIFS(Tickets!$B:$B,">="&$A17,Tickets!$B:$B,"<"&EDATE($A17,1),Tickets!$H:$H,H$5) -> 67 | I17: =COUNTIFS(Tickets!$B:$B,">="&$A17,Tickets!$B:$B,"<"&EDATE($A17,1),Tickets!$H:$H,I$5) -> 158 | J17: =SUM(B17:I17) -> 1097
A18: Total | B18: =SUM(B6:B17) -> 3161 | C18: =SUM(C6:C17) -> 1977 | D18: =SUM(D6:D17) -> 1592 | E18: =SUM(E6:E17) -> 1169 | F18: =SUM(F6:F17) -> 1880 | G18: =SUM(G6:G17) -> 733 | H18: =SUM(H6:H17) -> 735 | I18: =SUM(I6:I17) -> 1900 | J18: =SUM(J6:J17) -> 13147
A20: B. SLA results by assignment group
A21: Assignment_Group | B21: Tickets | C21: Resolved | D21: Met | E21: Breached | F21: Breach rate | G21: Open and breached | H21: Avg resolution hours
A22: Service Desk | B22: =COUNTIF(Tickets!$O:$O,$A22) -> 4101 | C22: =D22+E22 -> 4033 | D22: =COUNTIFS(Tickets!$O:$O,$A22,Tickets!$Y:$Y,"Met") -> 3925 | E22: =COUNTIFS(Tickets!$O:$O,$A22,Tickets!$Y:$Y,"Breached") -> 108 | F22: =IF(C22=0,0,E22/C22) -> 0.026779073 | G22: =COUNTIFS(Tickets!$O:$O,$A22,Tickets!$Y:$Y,"Open - Breached") -> 1 | H22: =IF(C22=0,0,SUMPRODUCT((Tickets!$O$2:$O$13148=$A22)*(Tickets!$D$2:$D$13148<>"")*(Tickets!$D$2:$D$13148-Tickets!$B$2:$B$13148))*24/C22) -> 17.297785
A23: Desktop Support | B23: =COUNTIF(Tickets!$O:$O,$A23) -> 2733 | C23: =D23+E23 -> 2669 | D23: =COUNTIFS(Tickets!$O:$O,$A23,Tickets!$Y:$Y,"Met") -> 2391 | E23: =COUNTIFS(Tickets!$O:$O,$A23,Tickets!$Y:$Y,"Breached") -> 278 | F23: =IF(C23=0,0,E23/C23) -> 0.10415886 | G23: =COUNTIFS(Tickets!$O:$O,$A23,Tickets!$Y:$Y,"Open - Breached") -> 9 | H23: =IF(C23=0,0,SUMPRODUCT((Tickets!$O$2:$O$13148=$A23)*(Tickets!$D$2:$D$13148<>"")*(Tickets!$D$2:$D$13148-Tickets!$B$2:$B$13148))*24/C23) -> 35.704321
A24: Identity and Access | B24: =COUNTIF(Tickets!$O:$O,$A24) -> 1226 | C24: =D24+E24 -> 1193 | D24: =COUNTIFS(Tickets!$O:$O,$A24,Tickets!$Y:$Y,"Met") -> 1124 | E24: =COUNTIFS(Tickets!$O:$O,$A24,Tickets!$Y:$Y,"Breached") -> 69 | F24: =IF(C24=0,0,E24/C24) -> 0.057837385 | G24: =COUNTIFS(Tickets!$O:$O,$A24,Tickets!$Y:$Y,"Open - Breached") -> 11 | H24: =IF(C24=0,0,SUMPRODUCT((Tickets!$O$2:$O$13148=$A24)*(Tickets!$D$2:$D$13148<>"")*(Tickets!$D$2:$D$13148-Tickets!$B$2:$B$13148))*24/C24) -> 31.461106
A25: Network Operations | B25: =COUNTIF(Tickets!$O:$O,$A25) -> 1509 | C25: =D25+E25 -> 1473 | D25: =COUNTIFS(Tickets!$O:$O,$A25,Tickets!$Y:$Y,"Met") -> 1353 | E25: =COUNTIFS(Tickets!$O:$O,$A25,Tickets!$Y:$Y,"Breached") -> 120 | F25: =IF(C25=0,0,E25/C25) -> 0.081466395 | G25: =COUNTIFS(Tickets!$O:$O,$A25,Tickets!$Y:$Y,"Open - Breached") -> 0 | H25: =IF(C25=0,0,SUMPRODUCT((Tickets!$O$2:$O$13148=$A25)*(Tickets!$D$2:$D$13148<>"")*(Tickets!$D$2:$D$13148-Tickets!$B$2:$B$13148))*24/C25) -> 27.882134
A26: Collaboration Services | B26: =COUNTIF(Tickets!$O:$O,$A26) -> 1373 | C26: =D26+E26 -> 1345 | D26: =COUNTIFS(Tickets!$O:$O,$A26,Tickets!$Y:$Y,"Met") -> 1248 | E26: =COUNTIFS(Tickets!$O:$O,$A26,Tickets!$Y:$Y,"Breached") -> 97 | F26: =IF(C26=0,0,E26/C26) -> 0.072118959 | G26: =COUNTIFS(Tickets!$O:$O,$A26,Tickets!$Y:$Y,"Open - Breached") -> 3 | H26: =IF(C26=0,0,SUMPRODUCT((Tickets!$O$2:$O$13148=$A26)*(Tickets!$D$2:$D$13148<>"")*(Tickets!$D$2:$D$13148-Tickets!$B$2:$B$13148))*24/C26) -> 31.476927
A27: Endpoint Engineering | B27: =COUNTIF(Tickets!$O:$O,$A27) -> 1467 | C27: =D27+E27 -> 1432 | D27: =COUNTIFS(Tickets!$O:$O,$A27,Tickets!$Y:$Y,"Met") -> 1061 | E27: =COUNTIFS(Tickets!$O:$O,$A27,Tickets!$Y:$Y,"Breached") -> 371 | F27: =IF(C27=0,0,E27/C27) -> 0.25907821 | G27: =COUNTIFS(Tickets!$O:$O,$A27,Tickets!$Y:$Y,"Open - Breached") -> 6 | H27: =IF(C27=0,0,SUMPRODUCT((Tickets!$O$2:$O$13148=$A27)*(Tickets!$D$2:$D$13148<>"")*(Tickets!$D$2:$D$13148-Tickets!$B$2:$B$13148))*24/C27) -> 71.817842
A28: Security Operations | B28: =COUNTIF(Tickets!$O:$O,$A28) -> 657 | C28: =D28+E28 -> 648 | D28: =COUNTIFS(Tickets!$O:$O,$A28,Tickets!$Y:$Y,"Met") -> 622 | E28: =COUNTIFS(Tickets!$O:$O,$A28,Tickets!$Y:$Y,"Breached") -> 26 | F28: =IF(C28=0,0,E28/C28) -> 0.040123457 | G28: =COUNTIFS(Tickets!$O:$O,$A28,Tickets!$Y:$Y,"Open - Breached") -> 0 | H28: =IF(C28=0,0,SUMPRODUCT((Tickets!$O$2:$O$13148=$A28)*(Tickets!$D$2:$D$13148<>"")*(Tickets!$D$2:$D$13148-Tickets!$B$2:$B$13148))*24/C28) -> 17.809053
A29: Program IT - Harbor Point | B29: =COUNTIF(Tickets!$O:$O,$A29) -> 81 | C29: =D29+E29 -> 77 | D29: =COUNTIFS(Tickets!$O:$O,$A29,Tickets!$Y:$Y,"Met") -> 77 | E29: =COUNTIFS(Tickets!$O:$O,$A29,Tickets!$Y:$Y,"Breached") -> 0 | F29: =IF(C29=0,0,E29/C29) -> 0 | G29: =COUNTIFS(Tickets!$O:$O,$A29,Tickets!$Y:$Y,"Open - Breached") -> 0 | H29: =IF(C29=0,0,SUMPRODUCT((Tickets!$O$2:$O$13148=$A29)*(Tickets!$D$2:$D$13148<>"")*(Tickets!$D$2:$D$13148-Tickets!$B$2:$B$13148))*24/C29) -> 16.27684
A30: All groups | B30: =SUM(B22:B29) -> 13147 | C30: =SUM(C22:C29) -> 12870 | D30: =SUM(D22:D29) -> 11801 | E30: =SUM(E22:E29) -> 1069 | F30: =IF(C30=0,0,E30/C30) -> 0.083061383 | G30: =SUM(G22:G29) -> 30 | H30: =IF(C30=0,0,SUMPRODUCT((Tickets!$D$2:$D$13148<>"")*(Tickets!$D$2:$D$13148-Tickets!$B$2:$B$13148))*24/C30) -> 31.206953
A32: C. SLA results by priority
A33: Priority | B33: Resolution target (hours) | C33: Tickets | D33: Resolved | E33: Breached | F33: Breach rate | G33: Avg resolution hours
A34: P1 - Critical | B34: =INDEX(SLA_Policy!$D$2:$D$5,MATCH($A34,SLA_Policy!$A$2:$A$5,0)) -> 4 | C34: =COUNTIF(Tickets!$F:$F,$A34) -> 79 | D34: =COUNTIFS(Tickets!$F:$F,$A34,Tickets!$Y:$Y,"Met")+E34 -> 79 | E34: =COUNTIFS(Tickets!$F:$F,$A34,Tickets!$Y:$Y,"Breached") -> 8 | F34: =IF(D34=0,0,E34/D34) -> 0.10126582 | G34: =IF(D34=0,0,SUMPRODUCT((Tickets!$F$2:$F$13148=$A34)*(Tickets!$D$2:$D$13148<>"")*(Tickets!$D$2:$D$13148-Tickets!$B$2:$B$13148))*24/D34) -> 2.1128692
A35: P2 - High | B35: =INDEX(SLA_Policy!$D$2:$D$5,MATCH($A35,SLA_Policy!$A$2:$A$5,0)) -> 8 | C35: =COUNTIF(Tickets!$F:$F,$A35) -> 1145 | D35: =COUNTIFS(Tickets!$F:$F,$A35,Tickets!$Y:$Y,"Met")+E35 -> 1120 | E35: =COUNTIFS(Tickets!$F:$F,$A35,Tickets!$Y:$Y,"Breached") -> 191 | F35: =IF(D35=0,0,E35/D35) -> 0.17053571 | G35: =IF(D35=0,0,SUMPRODUCT((Tickets!$F$2:$F$13148=$A35)*(Tickets!$D$2:$D$13148<>"")*(Tickets!$D$2:$D$13148-Tickets!$B$2:$B$13148))*24/D35) -> 6.2745833
A36: P3 - Medium | B36: =INDEX(SLA_Policy!$D$2:$D$5,MATCH($A36,SLA_Policy!$A$2:$A$5,0)) -> 72 | C36: =COUNTIF(Tickets!$F:$F,$A36) -> 7429 | D36: =COUNTIFS(Tickets!$F:$F,$A36,Tickets!$Y:$Y,"Met")+E36 -> 7283 | E36: =COUNTIFS(Tickets!$F:$F,$A36,Tickets!$Y:$Y,"Breached") -> 605 | F36: =IF(D36=0,0,E36/D36) -> 0.083070163 | G36: =IF(D36=0,0,SUMPRODUCT((Tickets!$F$2:$F$13148=$A36)*(Tickets!$D$2:$D$13148<>"")*(Tickets!$D$2:$D$13148-Tickets!$B$2:$B$13148))*24/D36) -> 27.261547
A37: P4 - Low | B37: =INDEX(SLA_Policy!$D$2:$D$5,MATCH($A37,SLA_Policy!$A$2:$A$5,0)) -> 120 | C37: =COUNTIF(Tickets!$F:$F,$A37) -> 4494 | D37: =COUNTIFS(Tickets!$F:$F,$A37,Tickets!$Y:$Y,"Met")+E37 -> 4388 | E37: =COUNTIFS(Tickets!$F:$F,$A37,Tickets!$Y:$Y,"Breached") -> 265 | F37: =IF(D37=0,0,E37/D37) -> 0.060391978 | G37: =IF(D37=0,0,SUMPRODUCT((Tickets!$F$2:$F$13148=$A37)*(Tickets!$D$2:$D$13148<>"")*(Tickets!$D$2:$D$13148-Tickets!$B$2:$B$13148))*24/D37) -> 44.642931
A39: D. Customer satisfaction by number of times reopened
A40: Reopen_Count | B40: Tickets | C40: Survey responses | D40: Avg CSAT (1 to 5)
A41: 0 | B41: =COUNTIF(Tickets!$R:$R,$A41) -> 12117 | C41: =COUNTIFS(Tickets!$R:$R,$A41,Tickets!$W:$W,">=1") -> 4023 | D41: =IF(C41=0,"",AVERAGEIFS(Tickets!$W:$W,Tickets!$R:$R,$A41)) -> 4.3686304
A42: 1 | B42: =COUNTIF(Tickets!$R:$R,$A42) -> 819 | C42: =COUNTIFS(Tickets!$R:$R,$A42,Tickets!$W:$W,">=1") -> 280 | D42: =IF(C42=0,"",AVERAGEIFS(Tickets!$W:$W,Tickets!$R:$R,$A42)) -> 3.3821429
A43: 2 | B43: =COUNTIF(Tickets!$R:$R,$A43) -> 171 | C43: =COUNTIFS(Tickets!$R:$R,$A43,Tickets!$W:$W,">=1") -> 61 | D43: =IF(C43=0,"",AVERAGEIFS(Tickets!$W:$W,Tickets!$R:$R,$A43)) -> 2.295082
A44: 3 | B44: =COUNTIF(Tickets!$R:$R,$A44) -> 40 | C44: =COUNTIFS(Tickets!$R:$R,$A44,Tickets!$W:$W,">=1") -> 18 | D44: =IF(C44=0,"",AVERAGEIFS(Tickets!$W:$W,Tickets!$R:$R,$A44)) -> 1.3888889
...

Sheet Tickets
A1: Ticket_ID | B1: Opened_At | C1: First_Response_At | D1: Resolved_At | E1: Status | F1: Priority | G1: Ticket_Type | H1: Category | I1: Subcategory | J1: Short_Description | K1: Site_Code | L1: Department | M1: Requester_ID | N1: Channel | O1: Assignment_Group | P1: Assigned_To | Q1: Escalated | R1: Reopen_Count | S1: Labor_Minutes | T1: Device_Model | U1: Root_Cause | V1: Related_Change_ID | W1: CSAT_Score | X1: SLA_Target_Hours | Y1: SLA_Result
A2: SD-35900 | B2: 45931.297 | C2: 45931.325 | D2: 45932.312 | E2: Closed | F2: P3 - Medium | G2: Incident | H2: Network and VPN | I2: VPN connectivity | J2: VPN asks for credentials repeatedly | K2: RMT | L2: Infrastructure Advisory | M2: MAG-28336 | N2: Portal | O2: Service Desk | P2: Kwame Asante | Q2: No | R2: 0 | S2: 20 | T2: Kestrel 14 G4 | U2: Expired credential or certificate | X2: =INDEX(SLA_Policy!$D$2:$D$5,MATCH(F2,SLA_Policy!$A$2:$A$5,0)) -> 72 | Y2: =IF(E2="Cancelled","Excluded",IF(D2="",IF((SLA_Policy!$B$8-B2)*24>X2,"Open - Breached","Open - On Track"),IF((D2-B2)*24<=X2,"Met","Breached"))) -> Met
A3: SD-35901 | B3: 45931.298 | C3: 45931.31 | D3: 45932.383 | E3: Closed | F3: P3 - Medium | G3: Incident | H3: Hardware | I3: Laptop hardware fault | J3: Blue screen on startup | K3: LKS | L3: Environmental Sciences | M3: MAG-28597 | N3: Portal | O3: Desktop Support | P3: Caleb Strand | Q3: No | R3: 0 | S3: 44 | T3: Kestrel 14 G2 | U3: Hardware fault | X3: =INDEX(SLA_Policy!$D$2:$D$5,MATCH(F3,SLA_Policy!$A$2:$A$5,0)) -> 72 | Y3: =IF(E3="Cancelled","Excluded",IF(D3="",IF((SLA_Policy!$B$8-B3)*24>X3,"Open - Breached","Open - On Track"),IF((D3-B3)*24<=X3,"Met","Breached"))) -> Met
A4: SD-35902 | B4: 45931.319 | C4: 45931.338 | D4: 45932.53 | E4: Closed | F4: P4 - Low | G4: Incident | H4: Network and VPN | I4: VPN connectivity | J4: VPN very slow on video calls, intermittent | K4: RMT | L4: Environmental Sciences | M4: MAG-15985 | N4: Phone | O4: Service Desk | P4: Mei-Ling Zhao | Q4: No | R4: 0 | S4: 13 | T4: Kestrel 14 G4 | U4: Hardware fault | X4: =INDEX(SLA_Policy!$D$2:$D$5,MATCH(F4,SLA_Policy!$A$2:$A$5,0)) -> 120 | Y4: =IF(E4="Cancelled","Excluded",IF(D4="",IF((SLA_Policy!$B$8-B4)*24>X4,"Open - Breached","Open - On Track"),IF((D4-B4)*24<=X4,"Met","Breached"))) -> Met
A5: SD-35903 | B5: 45931.328 | C5: 45931.356 | D5: 45932.394 | E5: Closed | F5: P4 - Low | G5: Service Request | H5: Account and Access | I5: Access request | J5: Permission to edit team calendar | K5: ANX | L5: Engineering Services | M5: MAG-18255 | N5: Portal | O5: Identity and Access | P5: Ines Caldeira | Q5: No | R5: 0 | S5: 12 | U5: Not applicable (request) | X5: =INDEX(SLA_Policy!$D$2:$D$5,MATCH(F5,SLA_Policy!$A$2:$A$5,0)) -> 120 | Y5: =IF(E5="Cancelled","Excluded",IF(D5="",IF((SLA_Policy!$B$8-B5)*24>X5,"Open - Breached","Open - On Track"),IF((D5-B5)*24<=X5,"Met","Breached"))) -> Met
A6: SD-35904 | B6: 45931.342 | C6: 45931.353 | D6: 45931.472 | E6: Closed | F6: P3 - Medium | G6: Incident | H6: Email and Collaboration | I6: SharePoint or OneDrive sync | J6: OneDrive sync stuck on processing changes, urgent | K6: HQ | L6: Infrastructure Advisory | M6: MAG-14447 | N6: Portal | O6: Service Desk | P6: Kwame Asante | Q6: No | R6: 0 | S6: 26 | U6: Software defect | W6: 4 | X6: =INDEX(SLA_Policy!$D$2:$D$5,MATCH(F6,SLA_Policy!$A$2:$A$5,0)) -> 72 | Y6: =IF(E6="Cancelled","Excluded",IF(D6="",IF((SLA_Policy!$B$8-B6)*24>X6,"Open - Breached","Open - On Track"),IF((D6-B6)*24<=X6,"Met","Breached"))) -> Met
A7: SD-35905 | B7: 45931.342 | C7: 45931.385 | D7: 45932.674 | E7: Closed | F7: P4 - Low | G7: Incident | H7: Hardware | I7: Docking station or monitor | J7: Docking station not charging laptop | K7: HQ | L7: Engineering Services | M7: MAG-17101 | N7: Portal | O7: Desktop Support | P7: Yusuf Demir | Q7: No | R7: 0 | S7: 30 | T7: Kestrel 14 G2 | U7: Hardware fault | X7: =INDEX(SLA_Policy!$D$2:$D$5,MATCH(F7,SLA_Policy!$A$2:$A$5,0)) -> 120 | Y7: =IF(E7="Cancelled","Excluded",IF(D7="",IF((SLA_Policy!$B$8-B7)*24>X7,"Open - Breached","Open - On Track"),IF((D7-B7)*24<=X7,"Met","Breached"))) -> Met
A8: SD-35906 | B8: 45931.344 | C8: 45931.353 | D8: 45931.654 | E8: Closed | F8: P4 - Low | G8: Service Request | H8: Software | I8: Application install request | J8: Install hydraulic modeling suite on laptop, for a proposal deadline | K8: HQ | L8: Infrastructure Advisory | M8: MAG-15820 | N8: Phone | O8: Service Desk | P8: Darnell Whitcombe | Q8: No | R8: 0 | S8: 20 | U8: Not applicable (request) | X8: =INDEX(SLA_Policy!$D$2:$D$5,MATCH(F8,SLA_Policy!$A$2:$A$5,0)) -> 120 | Y8: =IF(E8="Cancelled","Excluded",IF(D8="",IF((SLA_Policy!$B$8-B8)*24>X8,"Open - Breached","Open - On Track"),IF((D8-B8)*24<=X8,"Met","Breached"))) -> Met
A9: SD-35907 | B9: 45931.344 | C9: 45931.509 | D9: 45933.367 | E9: Closed | F9: P3 - Medium | G9: Incident | H9: Mobile and Field Devices | I9: Tablet sync or upload | J9: Field tablet will not sync inspection forms, tried restarting | K9: SMR | L9: Infrastructure Advisory | M9: MAG-10826 | N9: Portal | O9: Collaboration Services | P9: Elspeth Munro | Q9: No | R9: 0 | S9: 23 | T9: FieldTab 10 Rugged | U9: Configuration | X9: =INDEX(SLA_Policy!$D$2:$D$5,MATCH(F9,SLA_Policy!$A$2:$A$5,0)) -> 72 | Y9: =IF(E9="Cancelled","Excluded",IF(D9="",IF((SLA_Policy!$B$8-B9)*24>X9,"Open - Breached","Open - On Track"),IF((D9-B9)*24<=X9,"Met","Breached"))) -> Met
A10: SD-35908 | B10: 45931.349 | C10: 45931.369 | D10: 45933.32 | E10: Closed | F10: P3 - Medium | G10: Incident | H10: Network and VPN | I10: Wi-Fi connectivity | J10: Cannot join corporate Wi-Fi after password change | K10: SMR | L10: Finance and Accounting | M10: MAG-21258 | N10: Portal | O10: Network Operations | P10: Colette Dufresne | Q10: Yes | R10: 0 | S10: 16 | T10: Kestrel 14 G2 | U10: Configuration | X10: =INDEX(SLA_Policy!$D$2:$D$5,MATCH(F10,SLA_Policy!$A$2:$A$5,0)) -> 72 | Y10: =IF(E10="Cancelled","Excluded",IF(D10="",IF((SLA_Policy!$B$8-B10)*24>X10,"Open - Breached","Open - On Track"),IF((D10-B10)*24<=X10,"Met","Breached"))) -> Met
A11: SD-35909 | B11: 45931.352 | C11: 45931.419 | D11: 45933.347 | E11: Closed | F11: P4 - Low | G11: Service Request | H11: Software | I11: Application install request | J11: Upgrade project scheduling tool to current version, no rush | K11: CBO | L11: Engineering Services | M11: MAG-16254 | N11: Portal | O11: Endpoint Engineering | P11: Viktor Sandoval | Q11: No | R11: 0 | S11: 26 | U11: Not applicable (request) | X11: =INDEX(SLA_Policy!$D$2:$D$5,MATCH(F11,SLA_Policy!$A$2:$A$5,0)) -> 120 | Y11: =IF(E11="Cancelled","Excluded",IF(D11="",IF((SLA_Policy!$B$8-B11)*24>X11,"Open - Breached","Open - On Track"),IF((D11-B11)*24<=X11,"Met","Breached"))) -> Met
A12: SD-35910 | B12: 45931.353 | C12: 45931.377 | D12: 45931.682 | E12: Closed | F12: P4 - Low | G12: Service Request | H12: Email and Collaboration | I12: Shared mailbox or distribution list | J12: Add members to distribution list, approved by manager | K12: HQ | L12: Information Technology | M12: MAG-12430 | N12: Portal | O12: Collaboration Services | P12: Farid Haddad | Q12: No | R12: 0 | S12: 10 | U12: Not applicable (request) | X12: =INDEX(SLA_Policy!$D$2:$D$5,MATCH(F12,SLA_Policy!$A$2:$A$5,0)) -> 120 | Y12: =IF(E12="Cancelled","Excluded",IF(D12="",IF((SLA_Policy!$B$8-B12)*24>X12,"Open - Breached","Open - On Track"),IF((D12-B12)*24<=X12,"Met","Breached"))) -> Met
A13: SD-35911 | B13: 45931.355 | C13: 45931.374 | D13: 45932.356 | E13: Closed | F13: P3 - Medium | G13: Incident | H13: Security | I13: Phishing report | J13: Voicemail notification email looks fake | K13: ANX | L13: Environmental Sciences | M13: MAG-14261 | N13: Chat | O13: Security Operations | P13: Linnea Bjork | Q13: Yes | R13: 0 | S13: 11 | U13: User error or training | W13: 4 | X13: =INDEX(SLA_Policy!$D$2:$D$5,MATCH(F13,SLA_Policy!$A$2:$A$5,0)) -> 72 | Y13: =IF(E13="Cancelled","Excluded",IF(D13="",IF((SLA_Policy!$B$8-B13)*24>X13,"Open - Breached","Open - On Track"),IF((D13-B13)*24<=X13,"Met","Breached"))) -> Met
A14: SD-35912 | B14: 45931.359 | C14: 45931.367 | D14: 45931.503 | E14: Closed | F14: P3 - Medium | G14: Incident | H14: Email and Collaboration | I14: SharePoint or OneDrive sync | J14: Cannot open file from SharePoint, access denied, user is traveling | K14: RMT | L14: Program Management Office | M14: MAG-12875 | N14: Portal | O14: Service Desk | P14: Sunita Pradhan | Q14: No | R14: 0 | S14: 77 | U14: Software defect | X14: =INDEX(SLA_Policy!$D$2:$D$5,MATCH(F14,SLA_Policy!$A$2:$A$5,0)) -> 72 | Y14: =IF(E14="Cancelled","Excluded",IF(D14="",IF((SLA_Policy!$B$8-B14)*24>X14,"Open - Breached","Open - On Track"),IF((D14-B14)*24<=X14,"Met","Breached"))) -> Met
A15: SD-35913 | B15: 45931.366 | C15: 45931.368 | D15: 45932.333 | E15: Closed | F15: P3 - Medium | G15: Incident | H15: Account and Access | I15: MFA enrollment or reset | J15: Number matching prompt fails at sign-in on a new laptop | K15: HQ | L15: Program Management Office | M15: MAG-12752 | N15: Walk-up | O15: Identity and Access | P15: Thea Lindgren | Q15: No | R15: 0 | S15: 10 | U15: Configuration | W15: 4 | X15: =INDEX(SLA_Policy!$D$2:$D$5,MATCH(F15,SLA_Policy!$A$2:$A$5,0)) -> 72 | Y15: =IF(E15="Cancelled","Excluded",IF(D15="",IF((SLA_Policy!$B$8-B15)*24>X15,"Open - Breached","Open - On Track"),IF((D15-B15)*24<=X15,"Met","Breached"))) -> Met
A16: SD-35914 | B16: 45931.368 | C16: 45931.406 | D16: 45933.382 | E16: Closed | F16: P3 - Medium | G16: Incident | H16: Hardware | I16: Docking station or monitor | J16: External monitors not detected through dock after the weekend | K16: NGT | L16: Engineering Services | M16: MAG-16077 | N16: Email | O16: Desktop Support | P16: Caleb Strand | Q16: Yes | R16: 1 | S16: 79 | T16: Kestrel 14 G3 | U16: Hardware fault | X16: =INDEX(SLA_Policy!$D$2:$D$5,MATCH(F16,SLA_Policy!$A$2:$A$5,0)) -> 72 | Y16: =IF(E16="Cancelled","Excluded",IF(D16="",IF((SLA_Policy!$B$8-B16)*24>X16,"Open - Breached","Open - On Track"),IF((D16-B16)*24<=X16,"Met","Breached"))) -> Met
A17: SD-35915 | B17: 45931.376 | C17: 45931.392 | D17: 45936.339 | E17: Closed | F17: P4 - Low | G17: Service Request | H17: Account and Access | I17: Access request | J17: Access to shared library for field operations, for a proposal deadline | K17: LKS | L17: Contracts and Compliance | M17: MAG-18644 | N17: Portal | O17: Identity and Access | P17: Thea Lindgren | Q17: No | R17: 0 | S17: 18 | U17: Not applicable (request) | W17: 4 | X17: =INDEX(SLA_Policy!$D$2:$D$5,MATCH(F17,SLA_Policy!$A$2:$A$5,0)) -> 120 | Y17: =IF(E17="Cancelled","Excluded",IF(D17="",IF((SLA_Policy!$B$8-B17)*24>X17,"Open - Breached","Open - On Track"),IF((D17-B17)*24<=X17,"Met","Breached"))) -> Met
A18: SD-35916 | B18: 45931.378 | C18: 45931.475 | D18: 45932.369 | E18: Closed | F18: P4 - Low | G18: Service Request | H18: Email and Collaboration | I18: Shared mailbox or distribution list | J18: Need shared mailbox for field operations | K18: ANX | L18: Resilience and Climate Analytics | M18: MAG-16823 | N18: Portal | O18: Collaboration Services | P18: Dmitri Halvorsen | Q18: No | R18: 0 | S18: 13 | U18: Not applicable (request) | W18: 4 | X18: =INDEX(SLA_Policy!$D$2:$D$5,MATCH(F18,SLA_Policy!$A$2:$A$5,0)) -> 120 | Y18: =IF(E18="Cancelled","Excluded",IF(D18="",IF((SLA_Policy!$B$8-B18)*24>X18,"Open - Breached","Open - On Track"),IF((D18-B18)*24<=X18,"Met","Breached"))) -> Met
A19: SD-35917 | B19: 45931.399 | C19: 45931.522 | D19: 45936.34 | E19: Closed | F19: P4 - Low | G19: Service Request | H19: Hardware | I19: Laptop replacement or refresh | J19: Replacement for damaged laptop, cracked screen | K19: RMT | L19: Infrastructure Advisory | M19: MAG-11408 | N19: Portal | O19: Endpoint Engineering | P19: Greta Holloway | Q19: No | R19: 0 | S19: 98 | T19: Kestrel 14 G2 | U19: Not applicable (request) | W19: 4 | X19: =INDEX(SLA_Policy!$D$2:$D$5,MATCH(F19,SLA_Policy!$A$2:$A$5,0)) -> 120 | Y19: =IF(E19="Cancelled","Excluded",IF(D19="",IF((SLA_Policy!$B$8-B19)*24>X19,"Open - Breached","Open - On Track"),IF((D19-B19)*24<=X19,"Met","Breached"))) -> Met
A20: SD-35918 | B20: 45931.404 | C20: 45931.408 | D20: 45931.447 | E20: Closed | F20: P2 - High | G20: Incident | H20: Network and VPN | I20: VPN connectivity | J20: VPN disconnects every few minutes | K20: RMT | L20: Engineering Services | M20: MAG-10762 | N20: Chat | O20: Network Operations | P20: Signe Aaltonen | Q20: Yes | R20: 0 | S20: 20 | T20: Kestrel 16 Pro | U20: Expired credential or certificate | X20: =INDEX(SLA_Policy!$D$2:$D$5,MATCH(F20,SLA_Policy!$A$2:$A$5,0)) -> 8 | Y20: =IF(E20="Cancelled","Excluded",IF(D20="",IF((SLA_Policy!$B$8-B20)*24>X20,"Open - Breached","Open - On Track"),IF((D20-B20)*24<=X20,"Met","Breached"))) -> Met
A21: SD-35919 | B21: 45931.412 | C21: 45931.413 | D21: 45932.618 | E21: Closed | F21: P3 - Medium | G21: Incident | H21: Hardware | I21: Laptop hardware fault | J21: Screen flickering with lines on display | K21: NGT | L21: Engineering Services | M21: MAG-23572 | N21: Phone | O21: Desktop Support | P21: Caleb Strand | Q21: No | R21: 0 | S21: 81 | T21: Kestrel 14 G2 | U21: Hardware fault | W21: 5 | X21: =INDEX(SLA_Policy!$D$2:$D$5,MATCH(F21,SLA_Policy!$A$2:$A$5,0)) -> 72 | Y21: =IF(E21="Cancelled","Excluded",IF(D21="",IF((SLA_Policy!$B$8-B21)*24>X21,"Open - Breached","Open - On Track"),IF((D21-B21)*24<=X21,"Met","Breached"))) -> Met
A22: SD-35920 | B22: 45931.43 | C22: 45931.465 | D22: 45932.381 | E22: Closed | F22: P4 - Low | G22: Service Request | H22: Hardware | I22: Loaner device request | J22: Spare laptop for visiting staff | K22: HQ | L22: Engineering Services | M22: MAG-22227 | N22: Portal | O22: Desktop Support | P22: Petra Novak | Q22: Yes | R22: 0 | S22: 20 | U22: Not applicable (request) | X22: =INDEX(SLA_Policy!$D$2:$D$5,MATCH(F22,SLA_Policy!$A$2:$A$5,0)) -> 120 | Y22: =IF(E22="Cancelled","Excluded",IF(D22="",IF((SLA_Policy!$B$8-B22)*24>X22,"Open - Breached","Open - On Track"),IF((D22-B22)*24<=X22,"Met","Breached"))) -> Met
A23: SD-35921 | B23: 45931.436 | C23: 45931.549 | D23: 45932.762 | E23: Closed | F23: P4 - Low | G23: Service Request | H23: Account and Access | I23: Access request | J23: Read access to finance reporting folder, no rush | K23: ANX | L23: Infrastructure Advisory | M23: MAG-25793 | N23: Portal | O23: Collaboration Services | P23: Farid Haddad | Q23: No | R23: 0 | S23: 18 | U23: Not applicable (request) | X23: =INDEX(SLA_Policy!$D$2:$D$5,MATCH(F23,SLA_Policy!$A$2:$A$5,0)) -> 120 | Y23: =IF(E23="Cancelled","Excluded",IF(D23="",IF((SLA_Policy!$B$8-B23)*24>X23,"Open - Breached","Open - On Track"),IF((D23-B23)*24<=X23,"Met","Breached"))) -> Met
A24: SD-35922 | B24: 45931.441 | C24: 45931.463 | D24: 45932.316 | E24: Closed | F24: P4 - Low | G24: Incident | H24: Email and Collaboration | I24: SharePoint or OneDrive sync | J24: OneDrive shows file conflicts | K24: HQ | L24: Engineering Services | M24: MAG-13521 | N24: Portal | O24: Collaboration Services | P24: Naomi Eastman | Q24: No | R24: 0 | S24: 27 | U24: User error or training | W24: 5 | X24: =INDEX(SLA_Policy!$D$2:$D$5,MATCH(F24,SLA_Policy!$A$2:$A$5,0)) -> 120 | Y24: =IF(E24="Cancelled","Excluded",IF(D24="",IF((SLA_Policy!$B$8-B24)*24>X24,"Open - Breached","Open - On Track"),IF((D24-B24)*24<=X24,"Met","Breached"))) -> Met
A25: SD-35923 | B25: 45931.456 | C25: 45931.497 | D25: 45931.653 | E25: Closed | F25: P3 - Medium | G25: Incident | H25: Mobile and Field Devices | I25: Mobile app issue | J25: Mobile app asks to sign in every time | K25: RMT | L25: Infrastructure Advisory | M25: MAG-12308 | N25: Chat | O25: Service Desk | P25: Jonas Petrakis | Q25: No | R25: 0 | S25: 7 | T25: Managed phone (iOS) | U25: User error or training | X25: =INDEX(SLA_Policy!$D$2:$D$5,MATCH(F25,SLA_Policy!$A$2:$A$5,0)) -> 72 | Y25: =IF(E25="Cancelled","Excluded",IF(D25="",IF((SLA_Policy!$B$8-B25)*24>X25,"Open - Breached","Open - On Track"),IF((D25-B25)*24<=X25,"Met","Breached"))) -> Met
A26: SD-35924 | B26: 45931.468 | C26: 45931.501 | D26: 45932.328 | E26: Closed | F26: P3 - Medium | G26: Incident | H26: Email and Collaboration | I26: Outlook or mailbox issue | J26: Emails stuck in outbox, urgent | K26: ANX | L26: Infrastructure Advisory | M26: MAG-28423 | N26: Portal | O26: Collaboration Services | P26: Elspeth Munro | Q26: No | R26: 0 | S26: 67 | U26: Configuration | X26: =INDEX(SLA_Policy!$D$2:$D$5,MATCH(F26,SLA_Policy!$A$2:$A$5,0)) -> 72 | Y26: =IF(E26="Cancelled","Excluded",IF(D26="",IF((SLA_Policy!$B$8-B26)*24>X26,"Open - Breached","Open - On Track"),IF((D26-B26)*24<=X26,"Met","Breached"))) -> Met
A27: SD-35925 | B27: 45931.471 | C27: 45931.656 | D27: 45933.401 | E27: Closed | F27: P4 - Low | G27: Incident | H27: Software | I27: License or activation | J27: Office apps asking to activate since this morning | K27: RMT | L27: Business Development | M27: MAG-17942 | N27: Portal | O27: Service Desk | P27: Sunita Pradhan | Q27: No | R27: 0 | S27: 21 | U27: Configuration | W27: 3 | X27: =INDEX(SLA_Policy!$D$2:$D$5,MATCH(F27,SLA_Policy!$A$2:$A$5,0)) -> 120 | Y27: =IF(E27="Cancelled","Excluded",IF(D27="",IF((SLA_Policy!$B$8-B27)*24>X27,"Open - Breached","Open - On Track"),IF((D27-B27)*24<=X27,"Met","Breached"))) -> Met
A28: SD-35926 | B28: 45931.477 | C28: 45931.531 | D28: 45936.314 | E28: Closed | F28: P3 - Medium | G28: Incident | H28: Network and VPN | I28: Remote desktop or VDI | J28: Virtual desktop will not launch when working from home | K28: LKS | L28: Environmental Sciences | M28: MAG-17415 | N28: Portal | O28: Endpoint Engineering | P28: Greta Holloway | Q28: No | R28: 1 | S28: 71 | T28: Kestrel 14 G4 | U28: Expired credential or certificate | W28: 1 | X28: =INDEX(SLA_Policy!$D$2:$D$5,MATCH(F28,SLA_Policy!$A$2:$A$5,0)) -> 72 | Y28: =IF(E28="Cancelled","Excluded",IF(D28="",IF((SLA_Policy!$B$8-B28)*24>X28,"Open - Breached","Open - On Track"),IF((D28-B28)*24<=X28,"Met","Breached"))) -> Breached
A29: SD-35927 | B29: 45931.478 | C29: 45931.48 | D29: 45932.385 | E29: Closed | F29: P3 - Medium | G29: Incident | H29: Network and VPN | I29: VPN connectivity | J29: VPN disconnects every few minutes after a restart | K29: HQ | L29: Engineering Services | M29: MAG-25244 | N29: Phone | O29: Network Operations | P29: Bruno Tavares | Q29: No | R29: 0 | S29: 26 | T29: Kestrel 14 G2 | U29: User error or training | W29: 5 | X29: =INDEX(SLA_Policy!$D$2:$D$5,MATCH(F29,SLA_Policy!$A$2:$A$5,0)) -> 72 | Y29: =IF(E29="Cancelled","Excluded",IF(D29="",IF((SLA_Policy!$B$8-B29)*24>X29,"Open - Breached","Open - On Track"),IF((D29-B29)*24<=X29,"Met","Breached"))) -> Met
A30: SD-35928 | B30: 45931.49 | C30: 45931.498 | D30: 45931.644 | E30: Closed | F30: P3 - Medium | G30: Incident | H30: Software | I30: Application error or crash | J30: Data visualization tool very slow since last week after the weekend | K30: HQ | L30: Engineering Services | M30: MAG-24164 | N30: Portal | O30: Desktop Support | P30: Petra Novak | Q30: No | R30: 0 | S30: 31 | U30: Software defect | X30: =INDEX(SLA_Policy!$D$2:$D$5,MATCH(F30,SLA_Policy!$A$2:$A$5,0)) -> 72 | Y30: =IF(E30="Cancelled","Excluded",IF(D30="",IF((SLA_Policy!$B$8-B30)*24>X30,"Open - Breached","Open - On Track"),IF((D30-B30)*24<=X30,"Met","Breached"))) -> Met
A31: SD-35929 | B31: 45931.501 | C31: 45931.619 | D31: 45932.588 | E31: Closed | F31: P4 - Low | G31: Service Request | H31: Hardware | I31: Loaner device request | J31: Loaner laptop for travel next week, for a new project | K31: NGT | L31: Information Technology | M31: MAG-25232 | N31: Portal | O31: Endpoint Engineering | P31: Akira Tanaka-Reyes | Q31: No | R31: 0 | S31: 21 | U31: Not applicable (request) | X31: =INDEX(SLA_Policy!$D$2:$D$5,MATCH(F31,SLA_Policy!$A$2:$A$5,0)) -> 120 | Y31: =IF(E31="Cancelled","Excluded",IF(D31="",IF((SLA_Policy!$B$8-B31)*24>X31,"Open - Breached","Open - On Track"),IF((D31-B31)*24<=X31,"Met","Breached"))) -> Met
A32: SD-35930 | B32: 45931.504 | C32: 45931.531 | D32: 45932.384 | E32: Closed | F32: P3 - Medium | G32: Incident | H32: Email and Collaboration | I32: SharePoint or OneDrive sync | J32: Files not syncing to project library | K32: RMT | L32: Human Resources | M32: MAG-21324 | N32: Email | O32: Collaboration Services | P32: Dmitri Halvorsen | Q32: No | R32: 0 | S32: 20 | U32: Configuration | X32: =INDEX(SLA_Policy!$D$2:$D$5,MATCH(F32,SLA_Policy!$A$2:$A$5,0)) -> 72 | Y32: =IF(E32="Cancelled","Excluded",IF(D32="",IF((SLA_Policy!$B$8-B32)*24>X32,"Open - Breached","Open - On Track"),IF((D32-B32)*24<=X32,"Met","Breached"))) -> Met
A33: SD-35931 | B33: 45931.56 | C33: 45931.579 | D33: 45932.593 | E33: Closed | F33: P3 - Medium | G33: Incident | H33: Software | I33: Application error or crash | J33: Statistics package add-in fails to load | K33: HQ | L33: Human Resources | M33: MAG-28669 | N33: Email | O33: Endpoint Engineering | P33: Akira Tanaka-Reyes | Q33: No | R33: 0 | S33: 41 | U33: Unknown or not determined | W33: 5 | X33: =INDEX(SLA_Policy!$D$2:$D$5,MATCH(F33,SLA_Policy!$A$2:$A$5,0)) -> 72 | Y33: =IF(E33="Cancelled","Excluded",IF(D33="",IF((SLA_Policy!$B$8-B33)*24>X33,"Open - Breached","Open - On Track"),IF((D33-B33)*24<=X33,"Met","Breached"))) -> Met
A34: SD-35932 | B34: 45931.562 | C34: 45931.578 | D34: 45936.38 | E34: Closed | F34: P4 - Low | G34: Incident | H34: Security | I34: Encryption or compliance flag | J34: Compliance check failing, email blocked at the client site | K34: NGT | L34: Contracts and Compliance | M34: MAG-12425 | N34: Phone | O34: Endpoint Engineering | P34: Noor Fairweather | Q34: No | R34: 0 | S34: 53 | T34: Kestrel 14 G2 | U34: User error or training | W34: 4 | X34: =INDEX(SLA_Policy!$D$2:$D$5,MATCH(F34,SLA_Policy!$A$2:$A$5,0)) -> 120 | Y34: =IF(E34="Cancelled","Excluded",IF(D34="",IF((SLA_Policy!$B$8-B34)*24>X34,"Open - Breached","Open - On Track"),IF((D34-B34)*24<=X34,"Met","Breached"))) -> Met
A35: SD-35933 | B35: 45931.583 | C35: 45931.623 | D35: 45931.683 | E35: Closed | F35: P3 - Medium | G35: Incident | H35: Security | I35: Phishing report | J35: Unexpected MFA prompt after suspicious email | K35: RMT | L35: Finance and Accounting | M35: MAG-22968 | N35: Email | O35: Security Operations | P35: Linnea Bjork | Q35: No | R35: 0 | S35: 13 | U35: Unknown or not determined | X35: =INDEX(SLA_Policy!$D$2:$D$5,MATCH(F35,SLA_Policy!$A$2:$A$5,0)) -> 72 | Y35: =IF(E35="Cancelled","Excluded",IF(D35="",IF((SLA_Policy!$B$8-B35)*24>X35,"Open - Breached","Open - On Track"),IF((D35-B35)*24<=X35,"Met","Breached"))) -> Met
A36: SD-35934 | B36: 45931.592 | C36: 45931.76 | D36: 45936.386 | E36: Closed | F36: P4 - Low | G36: Incident | H36: Mobile and Field Devices | I36: Tablet sync or upload | J36: Inspection app will not open on tablet since yesterday | K36: HQ | L36: Engineering Services | M36: MAG-20602 | N36: Portal | O36: Endpoint Engineering | P36: Akira Tanaka-Reyes | Q36: Yes | R36: 1 | S36: 45 | T36: FieldTab 10 Rugged | U36: Configuration | W36: 2 | X36: =INDEX(SLA_Policy!$D$2:$D$5,MATCH(F36,SLA_Policy!$A$2:$A$5,0)) -> 120 | Y36: =IF(E36="Cancelled","Excluded",IF(D36="",IF((SLA_Policy!$B$8-B36)*24>X36,"Open - Breached","Open - On Track"),IF((D36-B36)*24<=X36,"Met","Breached"))) -> Met
A37: SD-35935 | B37: 45931.595 | C37: 45931.605 | D37: 45931.622 | E37: Closed | F37: P3 - Medium | G37: Incident | H37: Account and Access | I37: Password reset | J37: Need password reset before client call, needed before a client meeting | K37: RMT | L37: Engineering Services | M37: MAG-29776 | N37: Phone | O37: Service Desk | P37: Sunita Pradhan | Q37: No | R37: 0 | S37: 5 | U37: Expired credential or certificate | X37: =INDEX(SLA_Policy!$D$2:$D$5,MATCH(F37,SLA_Policy!$A$2:$A$5,0)) -> 72 | Y37: =IF(E37="Cancelled","Excluded",IF(D37="",IF((SLA_Policy!$B$8-B37)*24>X37,"Open - Breached","Open - On Track"),IF((D37-B37)*24<=X37,"Met","Breached"))) -> Met
A38: SD-35936 | B38: 45931.596 | C38: 45931.609 | D38: 45931.673 | E38: Closed | F38: P3 - Medium | G38: Incident | H38: Email and Collaboration | I38: Teams meeting or audio | J38: Teams camera not working, tried restarting | K38: SMR | L38: Executive Office | M38: MAG-12798 | N38: Phone | O38: Collaboration Services | P38: Farid Haddad | Q38: No | R38: 0 | S38: 14 | U38: Unknown or not determined | X38: =INDEX(SLA_Policy!$D$2:$D$5,MATCH(F38,SLA_Policy!$A$2:$A$5,0)) -> 72 | Y38: =IF(E38="Cancelled","Excluded",IF(D38="",IF((SLA_Policy!$B$8-B38)*24>X38,"Open - Breached","Open - On Track"),IF((D38-B38)*24<=X38,"Met","Breached"))) -> Met
A39: SD-35937 | B39: 45931.603 | C39: 45931.608 | D39: 45931.707 | E39: Closed | F39: P1 - Critical | G39: Incident | H39: Security | I39: Malware or endpoint alert | J39: Endpoint protection alert on laptop | K39: HQ | L39: Business Development | M39: MAG-23230 | N39: Email | O39: Security Operations | P39: Linnea Bjork | Q39: Yes | R39: 0 | S39: 101 | U39: User error or training | X39: =INDEX(SLA_Policy!$D$2:$D$5,MATCH(F39,SLA_Policy!$A$2:$A$5,0)) -> 4 | Y39: =IF(E39="Cancelled","Excluded",IF(D39="",IF((SLA_Policy!$B$8-B39)*24>X39,"Open - Breached","Open - On Track"),IF((D39-B39)*24<=X39,"Met","Breached"))) -> Met
A40: SD-35938 | B40: 45931.608 | C40: 45931.689 | D40: 45947.333 | E40: Closed | F40: P4 - Low | G40: Service Request | H40: Hardware | I40: Laptop replacement or refresh | J40: Request higher memory laptop for modeling work, no rush | K40: LKS | L40: Engineering Services | M40: MAG-16728 | N40: Portal | O40: Endpoint Engineering | P40: Noor Fairweather | Q40: No | R40: 0 | S40: 137 | T40: Kestrel 14 G2 | U40: Not applicable (request) | X40: =INDEX(SLA_Policy!$D$2:$D$5,MATCH(F40,SLA_Policy!$A$2:$A$5,0)) -> 120 | Y40: =IF(E40="Cancelled","Excluded",IF(D40="",IF((SLA_Policy!$B$8-B40)*24>X40,"Open - Breached","Open - On Track"),IF((D40-B40)*24<=X40,"Met","Breached"))) -> Breached
...

Sheet SLA_Policy
A1: Priority | B1: Meaning | C1: Response_Target_Minutes | D1: Resolution_Target_Hours | E1: Notes
A2: P1 - Critical | B2: Service down for many people, or a security emergency | C2: 15 | D2: 4 | E2: On-call response at any hour
A3: P2 - High | B3: One person or team cannot work, no workaround | C3: 30 | D3: 8 | E3: Major incidents are worked at this priority or higher
A4: P3 - Medium | B4: Work is slowed, a workaround exists | C4: 240 | D4: 72 | E4: Default for most incidents
A5: P4 - Low | B5: Routine request or minor inconvenience | C5: 480 | D5: 120 | E5: Default for most service requests
A7: Setting | B7: Value | C7: Notes
A8: Report_As_Of | B8: 46295.999 | C8: Open tickets are measured against this date and time. Entered as a fixed value so results do not change from day to day.
A9: SLA_Clock | B9: Calendar hours | C9: Targets run on calendar hours, including nights and weekends. Cancelled tickets are excluded from SLA results.

Sheet Sites
A1: Site_Code | B1: Site_Name | C1: Site_Type | D1: Headcount | E1: On_Site_Support | F1: Notes
A2: HQ | B2: Marrowstone Headquarters | C2: Headquarters | D2: 520 | E2: Yes
A3: ANX | B3: Headquarters Annex | C3: Headquarters | D3: 150 | E3: Yes
A4: NGT | B4: Northgate Regional Office | C4: Regional office | D4: 165 | E4: Yes
A5: LKS | B5: Lakeshore Regional Office | C5: Regional office | D5: 120 | E5: Yes
A6: SMR | B6: Summit Ridge Regional Office | C6: Regional office | D6: 95 | E6: Yes
A7: CBO | B7: Calder Bay Program Office | C7: Program office | D7: 28 | E7: Yes | F7: Harbor Point program office (19 program staff) plus 9 other staff
A8: HPF | B8: Harbor Point Field Office | C8: Field office | D8: 12 | E8: No | F8: Calder Bay wharf. 12 field staff. Field inspection began July 13, 2026
A9: GRV | B9: Greaves Landing Field Office | C9: Field office | D9: 16 | E9: No | F9: Field office for a separate program
A10: RMT | B10: Remote (full-time telework) | C10: Remote | D10: 234 | E10: No | F10: Devices are shipped for repair or replacement

Sheet Departments
A1: Department | B1: Headcount | C1: Notes
A2: Infrastructure Advisory | B2: 286
A3: Engineering Services | B3: 244
A4: Resilience and Climate Analytics | B4: 171
A5: Environmental Sciences | B5: 138
A6: Program Management Office | B6: 96
A7: Information Technology | B7: 88 | C7: Includes all eight support groups
A8: Finance and Accounting | B8: 82
A9: Business Development | B9: 74
A10: Contracts and Compliance | B10: 58
A11: Human Resources | B11: 41
A12: Executive Office | B12: 31 | C12: Executive requests are often raised one priority level
A13: Harbor Point Program | B13: 31 | C13: Harbor Point Resilience Assessment for the Calder Bay Port Authority. Mobilized May 2026
A14: Total | B14: =SUM(B2:B13) -> 1340

Sheet Assignment_Groups
A1: Assignment_Group | B1: Tier | C1: Lead | D1: Staff | E1: Coverage | F1: Scope
A2: Service Desk | B2: Tier 1 | C2: Rafael Quintanilla-Moss | D2: 9 | E2: Weekdays 7:00 AM to 7:00 PM Eastern, on-call after hours | F2: First contact, passwords, basic software and collaboration support
A3: Desktop Support | B3: Tier 2 | C3: Marguerite Okoro | D3: 7 | E3: Weekdays 7:00 AM to 6:30 PM Eastern | F3: Hardware faults, peripherals, printing, on-site visits
A4: Identity and Access | B4: Tier 2 | C4: Stellan Varga | D4: 4 | E4: Weekdays | F4: Accounts, MFA, access requests, onboarding and offboarding
A5: Network Operations | B5: Tier 2 and 3 | C5: Ifeoma Castellan | D5: 5 | E5: Weekdays, on-call after hours | F5: VPN, Wi-Fi, wired network, remote access
A6: Collaboration Services | B6: Tier 2 and 3 | C6: Dmitri Halvorsen | D6: 4 | E6: Weekdays | F6: Email, Teams, SharePoint and OneDrive, shared mailboxes
A7: Endpoint Engineering | B7: Tier 3 | C7: Noor Fairweather | D7: 4 | E7: Weekdays | F7: Device builds, refresh and replacement, patching, mobile device management
A8: Security Operations | B8: Tier 3 | C8: Callum Abernathy | D8: 4 | E8: Weekdays, on-call after hours | F8: Phishing, malware, lost devices, compliance
A9: Program IT - Harbor Point | B9: Embedded | C9: Ingrid Solberg-Achebe | D9: 2 | E9: Weekdays | F9: Program site, field tablets, and program access for the Harbor Point Resilience Assessment

Sheet Categories
A1: Category | B1: Subcategory | C1: Ticket_Type | D1: Default_Assignment_Group
A2: Account and Access | B2: Access request | C2: Service Request | D2: Identity and Access
A3: Account and Access | B3: Account lockout | C3: Incident | D3: Service Desk
A4: Account and Access | B4: MFA enrollment or reset | C4: Incident | D4: Identity and Access
A5: Account and Access | B5: New account or onboarding | C5: Service Request | D5: Identity and Access
A6: Account and Access | B6: Offboarding or access removal | C6: Service Request | D6: Identity and Access
A7: Account and Access | B7: Password reset | C7: Incident | D7: Service Desk
A8: Email and Collaboration | B8: Calendar or room booking | C8: Incident | D8: Collaboration Services
A9: Email and Collaboration | B9: Outlook or mailbox issue | C9: Incident | D9: Collaboration Services
A10: Email and Collaboration | B10: SharePoint or OneDrive sync | C10: Incident | D10: Collaboration Services
A11: Email and Collaboration | B11: Shared mailbox or distribution list | C11: Service Request | D11: Collaboration Services
A12: Email and Collaboration | B12: Teams meeting or audio | C12: Incident | D12: Service Desk
... A37: Software | B37: Operating system update issue | C37: Incident | D37: Endpoint Engineering

Sheet Change_Calendar
A1: Change_ID | B1: Scheduled_Start | C1: Change_Type | D1: Title | E1: Owner_Group | F1: Risk | G1: Peer_Reviewed | H1: Linked_Tickets | I1: Notes
A2: CHG-2025-0452 | B2: 45936.75 | C2: Standard | D2: Conference room display firmware update | E2: Collaboration Services | F2: Low | G2: No | H2: =COUNTIF(Tickets!$V:$V,A2) -> 6
A3: CHG-2025-0478 | B3: 45950.25 | C3: Normal | D3: Password policy update: minimum length raised to 14 characters | E3: Identity and Access | F3: Medium | G3: Yes | H3: =COUNTIF(Tickets!$V:$V,A3) -> 118 | I3: Staff communication sent October 16.
A4: CHG-2025-0511 | B4: 45966.792 | C4: Standard | D4: Printer driver package update (Headquarters and Annex) | E4: Desktop Support | F4: Low | G4: No | H4: =COUNTIF(Tickets!$V:$V,A4) -> 31
A5: CHG-2025-0534 | B5: 45979.833 | C5: Normal | D5: VPN gateway certificate renewal | E5: Network Operations | F5: Medium | G5: Yes | H5: =COUNTIF(Tickets!$V:$V,A5) -> 12
A6: CHG-2025-0563 | B6: 45994.771 | C6: Normal | D6: Email security gateway rule change | E6: Security Operations | F6: Medium | G6: Yes | H6: =COUNTIF(Tickets!$V:$V,A6) -> 24
A7: CHG-2025-0590 | B7: 46006.792 | C7: Standard | D7: Managed browser version update | E7: Endpoint Engineering | F7: Low | G7: No | H7: =COUNTIF(Tickets!$V:$V,A7) -> 14
A8: CHG-2026-0017 | B8: 46034.25 | C8: Normal | D8: MFA number matching enforced for all staff | E8: Identity and Access | F8: Medium | G8: Yes | H8: =COUNTIF(Tickets!$V:$V,A8) -> 96 | I8: Staff communication sent January 6.
A9: CHG-2026-0034 | B9: 46044.792 | C9: Normal | D9: Endpoint protection agent upgrade | E9: Security Operations | F9: Medium | G9: Yes | H9: =COUNTIF(Tickets!$V:$V,A9) -> 21
A10: CHG-2026-0052 | B10: 46056.833 | C10: Normal | D10: Wi-Fi controller firmware upgrade (Northgate Regional Office) | E10: Network Operations | F10: Medium | G10: Yes | H10: =COUNTIF(Tickets!$V:$V,A10) -> 27
A11: CHG-2026-0078 | B11: 46071.75 | C11: Normal | D11: License server migration (engineering applications) | E11: Endpoint Engineering | F11: Medium | G11: Yes | H11: =COUNTIF(Tickets!$V:$V,A11) -> 33
A12: CHG-2026-0107 | B12: 46090.25 | C12: Normal | D12: Remote access VPN client upgrade to version 6 (all laptops) | E12: Network Operations | F12: Medium | G12: Yes | H12: =COUNTIF(Tickets!$V:$V,A12) -> 520 | I12: Pilot group ran Kestrel 14 G4 laptops only. Rollback not used. Driver fix published March 24.
A13: CHG-2026-0141 | B13: 46111.792 | C13: Normal | D13: Mobile device management policy update | E13: Endpoint Engineering | F13: Medium | G13: Yes | H13: =COUNTIF(Tickets!$V:$V,A13) -> 29
A14: CHG-2026-0166 | B14: 46126.771 | C14: Standard | D14: Teams room system firmware update | E14: Collaboration Services | F14: Low | G14: No | H14: =COUNTIF(Tickets!$V:$V,A14) -> 19
A15: CHG-2026-0189 | B15: 46140.75 | C15: Standard | D15: Distribution list cleanup | E15: Collaboration Services | F15: Low | G15: No | H15: =COUNTIF(Tickets!$V:$V,A15) -> 11
A16: CHG-2026-0218 | B16: 46155.354 | C16: Standard | D16: Monthly permission cleanup job (Harbor Point program site) | E16: Program IT - Harbor Point | F16: Low | G16: No | H16: =COUNTIF(Tickets!$V:$V,A16) -> 0 | I16: First run of the job.
A17: CHG-2026-0233 | B17: 46163.792 | C17: Normal | D17: Network switch replacement (Lakeshore Regional Office) | E17: Network Operations | F17: Medium | G17: Yes | H17: =COUNTIF(Tickets!$V:$V,A17) -> 18
A18: CHG-2026-0259 | B18: 46181.792 | C18: Normal | D18: Operating system feature update, deployment ring 2 | E18: Endpoint Engineering | F18: Medium | G18: Yes | H18: =COUNTIF(Tickets!$V:$V,A18) -> 74
A19: CHG-2026-0262 | B19: 46183.354 | C19: Standard | D19: Monthly permission cleanup job (Harbor Point program site) | E19: Program IT - Harbor Point | F19: Low | G19: No | H19: =COUNTIF(Tickets!$V:$V,A19) -> 0
A20: CHG-2026-0290 | B20: 46202.75 | C20: Standard | D20: Plotter firmware update | E20: Desktop Support | F20: Low | G20: No | H20: =COUNTIF(Tickets!$V:$V,A20) -> 5
A21: CHG-2026-0301 | B21: 46211.354 | C21: Standard | D21: Monthly permission cleanup job (Harbor Point program site) | E21: Program IT - Harbor Point | F21: Low | G21: No | H21: =COUNTIF(Tickets!$V:$V,A21) -> 0
A22: CHG-2026-0318 | B22: 46223.792 | C22: Normal | D22: Field tablet inspection app update to version 3.2 | E22: Endpoint Engineering | F22: Low | G22: Yes | H22: =COUNTIF(Tickets!$V:$V,A22) -> 16
A23: CHG-2026-0338 | B23: 46233.75 | C23: Normal | D23: Disk encryption policy enforcement | E23: Security Operations | F23: Medium | G23: Yes | H23: =COUNTIF(Tickets!$V:$V,A23) -> 26
A24: CHG-2026-0357 | B24: 46246.354 | C24: Standard | D24: Monthly permission cleanup job (Harbor Point program site) | E24: Program IT - Harbor Point | F24: Low | G24: No | H24: =COUNTIF(Tickets!$V:$V,A24) -> 0
A25: CHG-2026-0371 | B25: 46252.771 | C25: Normal | D25: Outlook add-in deployment (records labeling) | E25: Collaboration Services | F25: Low | G25: Yes | H25: =COUNTIF(Tickets!$V:$V,A25) -> 38
A26: CHG-2026-0385 | B26: 46258.792 | C26: Standard | D26: Docking station firmware push | E26: Desktop Support | F26: Low | G26: No | H26: =COUNTIF(Tickets!$V:$V,A26) -> 17
A27: CHG-2026-0396 | B27: 46262.667 | C27: Standard | D27: Security group naming cleanup: HarborPoint-Members renamed to HP-Program-Members | E27: Program IT - Harbor Point | F27: Low | G27: No | H27: =COUNTIF(Tickets!$V:$V,A27) -> 0 | I27: Cleanup job allow list was not updated.
